<?xml version="1.0"?> 
<sdf version="1.4">
  <world name="default">

    <!-- Ground Plane -->
    <include>
      <uri>model://ground_plane</uri>
    </include>

    <include>
      <uri>model://sun</uri>
    </include>

    <model name="heightmap">
      <static>true</static>
      <link name="link">
        <collision name="collision">
          <geometry>
            <heightmap>
              <uri>file://media/materials/textures/terrain.png</uri>
              <size>129 129 10</size>
              <pos>0 0 0</pos>
            </heightmap>
          </geometry>
        </collision>

        <visual name="visual">
          <geometry>
            <heightmap>
              <texture>
                <diffuse>file://media/materials/textures/dirt_diffusespecular.png</diffuse>
                <normal>file://media/materials/textures/flat_normal.png</normal>
                <size>50</size>
              </texture>
              <texture>
                <diffuse>file://media/materials/textures/grass_diffusespecular.png</diffuse>
                <normal>file://media/materials/textures/flat_normal.png</normal>
                <size>20</size>
              </texture>
              <texture>
                <diffuse>file://media/materials/textures/fungus_diffusespecular.png</diffuse>
                <normal>file://media/materials/textures/flat_normal.png</normal>
                <size>80</size>
              </texture>
              <blend>
                <min_height>2</min_height>
                <fade_dist>5</fade_dist>
              </blend>
              <blend>
                <min_height>4</min_height>
                <fade_dist>5</fade_dist>
              </blend>
              <uri>file://media/materials/textures/terrain.png</uri>
              <size>129 129 10</size>
              <pos>0 0 0</pos>
            </heightmap>
          </geometry>
        </visual>
      </link>
    </model>

    <model name='asteroid'>
      <pose> 8 4 2.5 .4 0 0</pose>
      <link name='link_0'>
        <pose frame=''>-1.31567 -1.56631 -0.840454 0.970208 -0 0</pose>
        <gravity>1</gravity>
        <visual name='visual'>
          <pose frame=''>0 0 0 0 -0 0</pose>
          <geometry>
            <mesh>
              <uri>/Users/mabasta/HURC/meshes/eros.dae</uri>
              <scale>20 20 20</scale>
            </mesh>
          </geometry>
          <transparency>0</transparency>
          <cast_shadows>1</cast_shadows>
        </visual>
        <collision name='collision'>
          <pose frame=''>0 0 0 0 -0 0</pose>
          <geometry>
            <mesh>
              <uri>/Users/mabasta/HURC/meshes/eros.dae</uri>
              <scale>20 20 20</scale>
            </mesh>
          </geometry>
        </collision>

      </link>
      <static>1</static>
      <allow_auto_disable>1</allow_auto_disable>
      <pose frame=''>342.868 -244.293 0.579447 0.562946 -0.241822 -0.165365</pose>
    </model>

    <model name='itokawa'>
      <pose> -15 -5 1.5 -1 0 0</pose>
      <link name='link_0'>
        <pose frame=''>-1.31567 -1.56631 -0.840454 0.970208 -0 0</pose>
        <gravity>1</gravity>
        <visual name='visual'>
          <pose frame=''>0 0 0 0 -0 0</pose>
          <geometry>
            <mesh>
              <uri>/Users/mabasta/HURC/meshes/itokawa.dae</uri>
              <scale>20 20 20</scale>
            </mesh>
          </geometry>
          <transparency>0</transparency>
          <cast_shadows>1</cast_shadows>
        </visual>
        <collision name='collision'>
          <pose frame=''>0 0 0 0 -0 0</pose>
          <geometry>
            <mesh>
              <uri>/Users/mabasta/HURC/meshes/itokawa.dae</uri>
              <scale>20 20 20</scale>
            </mesh>
          </geometry>
        </collision>
      </link>
      <static>1</static>
      <allow_auto_disable>1</allow_auto_disable>
      <pose frame=''>342.868 -244.293 0.579447 0.562946 -0.241822 -0.165365</pose>
    </model>

    <model name='itokawa2'>
      <pose> 12 32 1.8 -1 0 0</pose>
      <link name='link_0'>
        <pose frame=''>-1.31567 -1.56631 -0.840454 0.970208 -0 0</pose>
        <gravity>1</gravity>
        <visual name='visual'>
          <pose frame=''>0 0 0 0 -0 0</pose>
          <geometry>
            <mesh>
              <uri>/Users/mabasta/HURC/meshes/itokawa.dae</uri>
              <scale>25 25 25</scale>
            </mesh>
          </geometry>
          <transparency>0</transparency>
          <cast_shadows>1</cast_shadows>
        </visual>
        <collision name='collision'>
          <pose frame=''>0 0 0 0 -0 0</pose>
          <geometry>
            <mesh>
              <uri>/Users/mabasta/HURC/meshes/itokawa.dae</uri>
              <scale>25 25 25</scale>
            </mesh>
          </geometry>
        </collision>
      </link>
      <static>1</static>
      <allow_auto_disable>1</allow_auto_disable>
      <pose frame=''>342.868 -244.293 0.579447 0.562946 -0.241822 -0.165365</pose>
    </model>


    <model name='rocks'>
      <pose> -8 12 2.5 .4 0 0</pose>
      <link name='link_0'>
        <pose frame=''>-1.31567 -1.56631 -0.840454 0.970208 -0 0</pose>
        <gravity>1</gravity>
        <visual name='visual'>
          <pose frame=''>0 0 0 0 -0 0</pose>
          <geometry>
            <mesh>
              <uri>/Users/mabasta/HURC/meshes/rocks_01_model.dae</uri>
              <scale>3 3 3</scale>
            </mesh>
          </geometry>
          <transparency>0</transparency>
          <cast_shadows>1</cast_shadows>
        </visual>
        <collision name='collision'>
          <pose frame=''>0 0 0 0 -0 0</pose>
          <geometry>
            <mesh>
              <uri>/Users/mabasta/HURC/meshes/rocks_01_model.dae</uri>
              <scale>3 3 3</scale>
            </mesh>
          </geometry>
        </collision>

      </link>
      <static>1</static>
      <allow_auto_disable>1</allow_auto_disable>
      <pose frame=''>342.868 -244.293 0.579447 0.562946 -0.241822 -0.165365</pose>
    </model>

    <model name='start_pole'>
      <pose>0 0 5 0 0 0</pose>
      <link name='unit_cylinder::link'>
        <visual name='visual'>
          <geometry>
            <cylinder>
              <radius>0.034805</radius>
              <length>5.81016</length>
            </cylinder>
          </geometry>
          <material>
            <ambient>0 1 0 1</ambient>
          </material>
          <pose frame=''>0 0 0 0 -0 0</pose>
          <transparency>-0</transparency>
          <cast_shadows>1</cast_shadows>
        </visual>
        <collision name='collision'>
          <pose frame=''>0 0 0 0 -0 0</pose>
          <geometry>
            <cylinder>
              <radius>0.034805</radius>
              <length>1.81016</length>
            </cylinder>
          </geometry>
        </collision>
      </link>
      <static>1</static>
      <allow_auto_disable>1</allow_auto_disable>
   </model>

    <model name='end_pole'>
      <pose>40 35 5 0 0 0</pose>
      <link name='unit_cylinder::link'>
        <visual name='visual'>
          <geometry>
            <cylinder>
              <radius>0.034805</radius>
              <length>5.81016</length>
            </cylinder>
          </geometry>
          <material>
            <ambient>1 0 0 1</ambient>
          </material>
          <pose frame=''>0 0 0 0 -0 0</pose>
          <transparency>-0</transparency>
          <cast_shadows>1</cast_shadows>
        </visual>
        <collision name='collision'>
          <pose frame=''>0 0 0 0 -0 0</pose>
          <geometry>
            <cylinder>
              <radius>0.034805</radius>
              <length>1.81016</length>
            </cylinder>
          </geometry>
        </collision>
      </link>
      <static>1</static>
      <allow_auto_disable>1</allow_auto_disable>
   </model>


    <model name="car">
    <pose>1 -1.5 5.5 0 0 0</pose>
    <link name='chassis'>
        <gravity>0</gravity>
          <pose>0 0 .2 0 0 0</pose>
          <inertial>
            <inertia>
              <ixx>1</ixx>
              <ixy>0</ixy>
              <ixz>0</ixz>
              <iyy>1</iyy>
              <iyz>0</iyz>
              <izz>1</izz>
            </inertia>
            <mass>5.0</mass>
          </inertial>
          <collision name='collision'>
            <geometry>
              <box>
                <size>1 .75 .1</size>
              </box>
            </geometry>
          </collision>

          <visual name='visual'>
            <geometry>
              <box>
                <size>1 .75 .1</size>
              </box>
            </geometry>
          </visual>
      </link>

      <link name="front_indicator">
        <pose>.5 0 0.3 0 0 0</pose>
          <geometry>
              <sphere>
              <radius>.03</radius>
            </sphere>
          </geometry>
        <visual name="visual">
          <geometry>
              <sphere>
              <radius>.03</radius>
            </sphere>
          </geometry>
          <material>Gazebo/Blue</material>
        </visual>
      </link>




      <link name="left_front_wheel">
        <pose>.5 .425 .1 0 0 1.5707</pose>
        <inertial>
          <inertia>
            <ixx>1</ixx>
            <ixy>0</ixy>
            <ixz>0</ixz>
            <iyy>1</iyy>
            <iyz>0</iyz>
            <izz>1</izz>
          </inertia>
          <mass>1.0</mass>
        </inertial>
        <collision name="collision">
          <geometry>
            <cylinder>
              <radius>.05</radius>
              <length>.4</length>
            </cylinder>
          </geometry>
        </collision>
        <visual name="visual">
          <geometry>
            <cylinder>
              <radius>.05</radius>
              <length>.4</length>
            </cylinder>
          </geometry>
        </visual>
      </link>


      <link name="right_front_wheel">
        <pose>.5 -.425 .1 0 0 1.5707</pose>
        <inertial>
          <inertia>
            <ixx>1</ixx>
            <ixy>0</ixy>
            <ixz>0</ixz>
            <iyy>1</iyy>
            <iyz>0</iyz>
            <izz>1</izz>
          </inertia>
          <mass>1.0</mass>
        </inertial>
        <collision name="collision">
          <geometry>
            <cylinder>
              <radius>.05</radius>
              <length>.4</length>
            </cylinder>
          </geometry>
        </collision>
        <visual name="visual">
          <geometry>
            <cylinder>
              <radius>.05</radius>
              <length>.4</length>
            </cylinder>
          </geometry>
        </visual>
      </link>


      <link name="left_middle_wheel">
        <pose>0 .425 .1 0 0 1.5707</pose>
        <inertial>
          <inertia>
            <ixx>1</ixx>
            <ixy>0</ixy>
            <ixz>0</ixz>
            <iyy>1</iyy>
            <iyz>0</iyz>
            <izz>1</izz>
          </inertia>
          <mass>1.0</mass>
        </inertial>
        <collision name="collision">
          <geometry>
            <cylinder>
              <radius>.05</radius>
              <length>.4</length>
            </cylinder>
          </geometry>
        </collision>
        <visual name="visual">
          <geometry>
            <cylinder>
              <radius>.05</radius>
              <length>.4</length>
            </cylinder>
          </geometry>
        </visual>
      </link>


      <link name="right_middle_wheel">
        <pose>0 -.425 .1 0 0 1.5707</pose>
        <inertial>
          <inertia>
            <ixx>1</ixx>
            <ixy>0</ixy>
            <ixz>0</ixz>
            <iyy>1</iyy>
            <iyz>0</iyz>
            <izz>1</izz>
          </inertia>
          <mass>1.0</mass>
        </inertial>
        <collision name="collision">
          <geometry>
            <cylinder>
              <radius>.05</radius>
              <length>.4</length>
            </cylinder>
          </geometry>
        </collision>
        <visual name="visual">
          <geometry>
            <cylinder>
              <radius>.05</radius>
              <length>.4</length>
            </cylinder>
          </geometry>
        </visual>
      </link>


      <link name="left_back_wheel">
        <pose>-.5 .425 .1 0 0 1.5707</pose>
        <inertial>
          <inertia>
            <ixx>1</ixx>
            <ixy>0</ixy>
            <ixz>0</ixz>
            <iyy>1</iyy>
            <iyz>0</iyz>
            <izz>1</izz>
          </inertia>
          <mass>1.0</mass>
        </inertial>
        <collision name="collision">
          <geometry>
            <cylinder>
              <radius>.05</radius>
              <length>.4</length>
            </cylinder>
          </geometry>
        </collision>
        <visual name="visual">
          <geometry>
            <cylinder>
              <radius>.05</radius>
              <length>.4</length>
            </cylinder>
          </geometry>
        </visual>
      </link>


      <link name="right_back_wheel">
        <pose>-.5 -.425 .1 0 0 1.5707</pose>
        <inertial>
          <inertia>
            <ixx>1</ixx>
            <ixy>0</ixy>
            <ixz>0</ixz>
            <iyy>1</iyy>
            <iyz>0</iyz>
            <izz>1</izz>
          </inertia>
          <mass>1.0</mass>
        </inertial>
        <collision name="collision">
          <geometry>
            <cylinder>
              <radius>.05</radius>
              <length>.4</length>
            </cylinder>
          </geometry>
        </collision>
        <visual name="visual">
          <geometry>
            <cylinder>
              <radius>.05</radius>
              <length>.4</length>
            </cylinder>
          </geometry>
        </visual>
      </link>


      <joint type="revolute" name="left_front_wheel_hinge">
        <pose>0 0 .1 0 0 0</pose>
        <child>left_front_wheel</child>
        <parent>chassis</parent>
        <axis>
          <xyz>0 1 0</xyz>
        </axis>
      </joint>


      <joint type="revolute" name="right_back_wheel_hinge">
        <pose>0 0 .1 0 0 0</pose>
        <child>right_back_wheel</child>
        <parent>chassis</parent>
        <axis>
          <xyz>0 1 0</xyz>
        </axis>
      </joint>


      <joint type="revolute" name="left_middle_wheel_hinge">
        <pose>0 0 .1 0 0 0</pose>
        <child>left_middle_wheel</child>
        <parent>chassis</parent>
        <axis>
          <xyz>0 1 0</xyz>
        </axis>
      </joint>


      <joint type="revolute" name="right_middle_wheel_hinge">
        <pose>0 0 .1 0 0 0</pose>
        <child>right_middle_wheel</child>
        <parent>chassis</parent>
        <axis>
          <xyz>0 1 0</xyz>
        </axis>
      </joint>


      <joint type="revolute" name="left_back_wheel_hinge">
        <pose>0 0 .1 0 0 0</pose>
        <child>left_back_wheel</child>
        <parent>chassis</parent>
        <axis>
          <xyz>0 1 0</xyz>
        </axis>
      </joint>


      <joint type="revolute" name="right_front_wheel_hinge">
        <pose>0 0 .1 0 0 0</pose>
        <child>right_front_wheel</child>
        <parent>chassis</parent>
        <axis>
          <xyz>0 1 0</xyz>
        </axis>
      </joint>


      <joint type="fixed" name="indicator_joint">
        <pose>0 0 0 0 0 0</pose>
        <child>front_indicator</child>
        <parent>chassis</parent>
      </joint>

      <plugin name="legged" filename="liblegged.so"/>
    </model>

</world>
</sdf>