<?xml version="1.0"?> 
<sdf version="1.4">
  <world name="default">

    <!-- Ground Plane -->
    <include>
      <uri>model://ground_plane</uri>
    </include>

    <include>
      <uri>model://sun</uri>
    </include>

    <model name="heightmap">
      <static>true</static>
      <link name="link">
        <collision name="collision">
          <geometry>
            <heightmap>
              <uri>file://media/materials/textures/terrain1.png</uri>
              <size>129 129 10</size>
              <pos>0 0 0</pos>
            </heightmap>
          </geometry>
          <surface>
            <friction>
              <torsional>
                <coefficient>1.0</coefficient>
                <surface_radius>0.5</surface_radius>
                <use_patch_radius>false</use_patch_radius>
              </torsional>
            </friction>
          </surface>
        </collision>

        <visual name="visual">
          <geometry>
            <heightmap>
              <texture>
                <diffuse>file://media/materials/textures/dirt_diffusespecular.png</diffuse>
                <normal>file://media/materials/textures/flat_normal.png</normal>
                <size>50</size>
              </texture>
              <texture>
                <diffuse>file://media/materials/textures/grass_diffusespecular.png</diffuse>
                <normal>file://media/materials/textures/flat_normal.png</normal>
                <size>20</size>
              </texture>
              <texture>
                <diffuse>file://media/materials/textures/fungus_diffusespecular.png</diffuse>
                <normal>file://media/materials/textures/flat_normal.png</normal>
                <size>80</size>
              </texture>
              <blend>
                <min_height>2</min_height>
                <fade_dist>5</fade_dist>
              </blend>
              <blend>
                <min_height>4</min_height>
                <fade_dist>5</fade_dist>
              </blend>
              <uri>file://media/materials/textures/terrain1.png</uri>
              <size>129 129 10</size>
              <pos>0 0 0</pos>
            </heightmap>
          </geometry>
        </visual>
      </link>
    </model>

    <model name='NEend_pole'>
      <pose>62 62 5 0 0 0</pose>
      <link name='unit_cylinder::link'>
        <visual name='visual'>
          <geometry>
            <cylinder>
              <radius>0.134805</radius>
              <length>5.81016</length>
            </cylinder>
          </geometry>
          <material>
            <ambient>1 0 0 1</ambient>
          </material>
          <pose frame=''>0 0 0 0 -0 0</pose>
          <transparency>-0</transparency>
          <cast_shadows>1</cast_shadows>
        </visual>
        <collision name='collision'>
          <pose frame=''>0 0 0 0 -0 0</pose>
          <geometry>
            <cylinder>
              <radius>0.034805</radius>
              <length>1.81016</length>
            </cylinder>
          </geometry>
        </collision>
      </link>
      <static>1</static>
      <allow_auto_disable>1</allow_auto_disable>
   </model>

    <model name='NEend_pole'>
      <pose>62 62 5 0 0 0</pose>
      <link name='unit_cylinder::link'>
        <visual name='visual'>
          <geometry>
            <cylinder>
              <radius>0.134805</radius>
              <length>5.81016</length>
            </cylinder>
          </geometry>
          <material>
            <ambient>1 0 0 1</ambient>
          </material>
          <pose frame=''>0 0 0 0 -0 0</pose>
          <transparency>-0</transparency>
          <cast_shadows>1</cast_shadows>
        </visual>
        <collision name='collision'>
          <pose frame=''>0 0 0 0 -0 0</pose>
          <geometry>
            <cylinder>
              <radius>0.034805</radius>
              <length>1.81016</length>
            </cylinder>
          </geometry>
        </collision>
      </link>
      <static>1</static>
      <allow_auto_disable>1</allow_auto_disable>
   </model>

   <model name='SEend_pole'>
      <pose>-62 62 5 0 0 0</pose>
      <link name='unit_cylinder::link'>
        <visual name='visual'>
          <geometry>
            <cylinder>
              <radius>0.134805</radius>
              <length>5.81016</length>
            </cylinder>
          </geometry>
          <material>
            <ambient>0 0 1 1</ambient>
          </material>
          <pose frame=''>0 0 0 0 -0 0</pose>
          <transparency>-0</transparency>
          <cast_shadows>1</cast_shadows>
        </visual>
        <collision name='collision'>
          <pose frame=''>0 0 0 0 -0 0</pose>
          <geometry>
            <cylinder>
              <radius>0.034805</radius>
              <length>1.81016</length>
            </cylinder>
          </geometry>
        </collision>
      </link>
      <static>1</static>
      <allow_auto_disable>1</allow_auto_disable>
   </model>

   <model name='NWend_pole'>
      <pose>62 -62 5 0 0 0</pose>
      <link name='unit_cylinder::link'>
        <visual name='visual'>
          <geometry>
            <cylinder>
              <radius>0.134805</radius>
              <length>5.81016</length>
            </cylinder>
          </geometry>
          <material>
            <ambient>1 1 0 1</ambient>
          </material>
          <pose frame=''>0 0 0 0 -0 0</pose>
          <transparency>-0</transparency>
          <cast_shadows>1</cast_shadows>
        </visual>
        <collision name='collision'>
          <pose frame=''>0 0 0 0 -0 0</pose>
          <geometry>
            <cylinder>
              <radius>0.034805</radius>
              <length>1.81016</length>
            </cylinder>
          </geometry>
        </collision>
      </link>
      <static>1</static>
      <allow_auto_disable>1</allow_auto_disable>
   </model>

   <model name='SWend_pole'>
      <pose>-62 -62 5 0 0 0</pose>
      <link name='unit_cylinder::link'>
        <visual name='visual'>
          <geometry>
            <cylinder>
              <radius>0.134805</radius>
              <length>5.81016</length>
            </cylinder>
          </geometry>
          <material>
            <ambient>0 0 0 1</ambient>
          </material>
          <pose frame=''>0 0 0 0 -0 0</pose>
          <transparency>-0</transparency>
          <cast_shadows>1</cast_shadows>
        </visual>
        <collision name='collision'>
          <pose frame=''>0 0 0 0 -0 0</pose>
          <geometry>
            <cylinder>
              <radius>0.134805</radius>
              <length>1.81016</length>
            </cylinder>
          </geometry>
        </collision>
      </link>
      <static>1</static>
      <allow_auto_disable>1</allow_auto_disable>
   </model>

    <model name="car">
    <pose>1 -1.5 7.5 0 0 0</pose>
    <link name='chassis'>
          <pose>0 0 .4 0 0 0</pose>
          <inertial>
            <inertia>
              <ixx>1</ixx>
              <ixy>0</ixy>
              <ixz>0</ixz>
              <iyy>1</iyy>
              <iyz>0</iyz>
              <izz>1</izz>
            </inertia>
            <mass>10.0</mass>
          </inertial>
          <collision name='collision'>
            <geometry>
              <box>
                <size>2 1.5 .2</size>
              </box>
            </geometry>
          </collision>

          <visual name='visual'>
            <geometry>
              <box>
                <size>2 1.5 .2</size>
              </box>
            </geometry>
            <material>
              <ambient>1 0 0 1</ambient>
              <shader type='vertex'>
                <normal_map>__default__</normal_map>
              </shader>
            </material>
          </visual>
      </link>

      <link name="front_indicator">
        <pose>1 0 0.6 0 0 0</pose>
          <geometry>
              <sphere>
              <radius>.06</radius>
            </sphere>
          </geometry>
        <visual name="visual">
          <geometry>
              <sphere>
              <radius>.06</radius>
            </sphere>
          </geometry>
          <material>Gazebo/Blue</material>
        </visual>
      </link>

      <link name="left_front_wheel">
        <pose>1 .85 .16 0 0 3.1414</pose>
        <inertial>
          <inertia>
            <ixx>1</ixx>
            <ixy>0</ixy>
            <ixz>0</ixz>
            <iyy>1</iyy>
            <iyz>0</iyz>
            <izz>1</izz>
          </inertia>
          <mass>2.0</mass>
        </inertial>
        <collision name="collision">
          <geometry>
            <cylinder>
              <radius>.1</radius>
              <length>.7</length>
            </cylinder>
          </geometry>
        </collision>
        <visual name="visual">
          <geometry>
            <cylinder>
              <radius>.1</radius>
              <length>.7</length>
            </cylinder>
          </geometry>
        </visual>
      </link>

      <link name="left_front_foot">
        <pose>1.1 .85 -.27 0 0 3.1414</pose>
        <inertial>
          <inertia>
            <ixx>1</ixx>
            <ixy>0</ixy>
            <ixz>0</ixz>
            <iyy>1</iyy>
            <iyz>0</iyz>
            <izz>1</izz>
          </inertia>
          <mass>2.0</mass>
        </inertial>
        <collision name="collision">
          <geometry>
            <box>
              <size>.4 .15 .15</size>
            </box>
          </geometry>
        </collision>
        <visual name="visual">
          <geometry>
            <box>
              <size>.4 .15 .15</size>
            </box>
          </geometry>
        </visual>
      </link>



      <link name="right_front_wheel">
        <pose>1 -.85 .16 0 0 3.1414</pose>
        <inertial>
          <inertia>
            <ixx>1</ixx>
            <ixy>0</ixy>
            <ixz>0</ixz>
            <iyy>1</iyy>
            <iyz>0</iyz>
            <izz>1</izz>
          </inertia>
          <mass>2.0</mass>
        </inertial>
        <collision name="collision">
          <geometry>
            <cylinder>
              <radius>.1</radius>
              <length>.7</length>
            </cylinder>
          </geometry>
        </collision>
        <visual name="visual">
          <geometry>
            <cylinder>
              <radius>.1</radius>
              <length>.7</length>
            </cylinder>
          </geometry>
        </visual>
      </link>

      <link name="right_front_foot">
        <pose>1.1 -.85 -.29 0 0 3.1414</pose>
        <inertial>
          <inertia>
            <ixx>1</ixx>
            <ixy>0</ixy>
            <ixz>0</ixz>
            <iyy>1</iyy>
            <iyz>0</iyz>
            <izz>1</izz>
          </inertia>
          <mass>2.0</mass>
        </inertial>
        <collision name="collision">
          <geometry>
            <box>
              <size>.4 .15 .15</size>
            </box>
          </geometry>
        </collision>
        <visual name="visual">
          <geometry>
            <box>
              <size>.4 .15 .15</size>
            </box>
          </geometry>
        </visual>
      </link>


      <link name="left_middle_wheel">
        <pose>0 .85 .16 0 0 3.1414</pose>
        <inertial>
          <inertia>
            <ixx>1</ixx>
            <ixy>0</ixy>
            <ixz>0</ixz>
            <iyy>1</iyy>
            <iyz>0</iyz>
            <izz>1</izz>
          </inertia>
          <mass>2.0</mass>
        </inertial>
        <collision name="collision">
          <geometry>
            <cylinder>
              <radius>.1</radius>
              <length>.7</length>
            </cylinder>
          </geometry>
        </collision>
        <visual name="visual">
          <geometry>
            <cylinder>
              <radius>.1</radius>
              <length>.7</length>
            </cylinder>
          </geometry>
        </visual>
      </link>

      <link name="left_middle_foot">
        <pose>.1 .85 -.29 0 0 3.1414</pose>
        <inertial>
          <inertia>
            <ixx>1</ixx>
            <ixy>0</ixy>
            <ixz>0</ixz>
            <iyy>1</iyy>
            <iyz>0</iyz>
            <izz>1</izz>
          </inertia>
          <mass>2.0</mass>
        </inertial>
        <collision name="collision">
          <geometry>
            <box>
              <size>.4 .15 .15</size>
            </box>
          </geometry>
        </collision>
        <visual name="visual">
          <geometry>
            <box>
              <size>.4 .15 .15</size>
            </box>
          </geometry>
        </visual>
      </link>


      <link name="right_middle_wheel">
        <pose>0 -.85 .16 0 0 3.1414</pose>
        <inertial>
          <inertia>
            <ixx>1</ixx>
            <ixy>0</ixy>
            <ixz>0</ixz>
            <iyy>1</iyy>
            <iyz>0</iyz>
            <izz>1</izz>
          </inertia>
          <mass>2.0</mass>
        </inertial>
        <collision name="collision">
          <geometry>
            <cylinder>
              <radius>.1</radius>
              <length>.7</length>
            </cylinder>
          </geometry>
        </collision>
        <visual name="visual">
          <geometry>
            <cylinder>
              <radius>.1</radius>
              <length>.7</length>
            </cylinder>
          </geometry>
        </visual>
      </link>

      <link name="right_middle_foot">
        <pose>.1 -.85 -.29 0 0 3.1414</pose>
        <inertial>
          <inertia>
            <ixx>1</ixx>
            <ixy>0</ixy>
            <ixz>0</ixz>
            <iyy>1</iyy>
            <iyz>0</iyz>
            <izz>1</izz>
          </inertia>
          <mass>2.0</mass>
        </inertial>
        <collision name="collision">
          <geometry>
            <box>
              <size>.4 .15 .15</size>
            </box>
          </geometry>
        </collision>
        <visual name="visual">
          <geometry>
            <box>
              <size>.4 .15 .15</size>
            </box>
          </geometry>
        </visual>
      </link>


      <link name="left_back_wheel">
        <pose>-1 .85 .16 0 0 3.1414</pose>
        <inertial>
          <inertia>
            <ixx>1</ixx>
            <ixy>0</ixy>
            <ixz>0</ixz>
            <iyy>1</iyy>
            <iyz>0</iyz>
            <izz>1</izz>
          </inertia>
          <mass>2.0</mass>
        </inertial>
        <collision name="collision">
          <geometry>
            <cylinder>
              <radius>.1</radius>
              <length>.7</length>
            </cylinder>
          </geometry>
        </collision>
        <visual name="visual">
          <geometry>
            <cylinder>
              <radius>.1</radius>
              <length>.7</length>
            </cylinder>
          </geometry>
        </visual>
      </link>

      <link name="left_back_foot">
        <pose>-.9 .85 -.29 0 0 3.1414</pose>
        <inertial>
          <inertia>
            <ixx>1</ixx>
            <ixy>0</ixy>
            <ixz>0</ixz>
            <iyy>1</iyy>
            <iyz>0</iyz>
            <izz>1</izz>
          </inertia>
          <mass>2.0</mass>
        </inertial>
        <collision name="collision">
          <geometry>
            <box>
              <size>.4 .15 .15</size>
            </box>
          </geometry>
        </collision>
        <visual name="visual">
          <geometry>
            <box>
              <size>.4 .15 .15</size>
            </box>
          </geometry>
        </visual>
      </link>


      <link name="right_back_wheel">
        <pose>-1 -.85 .16 0 0 3.1414</pose>
        <inertial>
          <inertia>
            <ixx>1</ixx>
            <ixy>0</ixy>
            <ixz>0</ixz>
            <iyy>1</iyy>
            <iyz>0</iyz>
            <izz>1</izz>
          </inertia>
          <mass>2.0</mass>
        </inertial>
        <collision name="collision">
          <geometry>
            <cylinder>
              <radius>.1</radius>
              <length>.7</length>
            </cylinder>
          </geometry>
        </collision>
        <visual name="visual">
          <geometry>
            <cylinder>
              <radius>.1</radius>
              <length>.7</length>
            </cylinder>
          </geometry>
        </visual>
      </link>

      <link name="right_back_foot">
        <pose>-.9 -.85 -.29 0 0 3.1414</pose>
        <inertial>
          <inertia>
            <ixx>1</ixx>
            <ixy>0</ixy>
            <ixz>0</ixz>
            <iyy>1</iyy>
            <iyz>0</iyz>
            <izz>1</izz>
          </inertia>
          <mass>2.0</mass>
        </inertial>
        <collision name="collision">
          <geometry>
            <box>
              <size>.4 .15 .15</size>
            </box>
          </geometry>
        </collision>
        <visual name="visual">
          <geometry>
            <box>
              <size>.4 .15 .15</size>
            </box>
          </geometry>
        </visual>
      </link>


      <joint type="revolute" name="left_front_wheel_hinge">
        <pose>0 0 .1 0 0 0</pose>
        <child>left_front_wheel</child>
        <parent>chassis</parent>
        <axis>
          <xyz>0 1 0</xyz>
        </axis>
      </joint>


      <joint type="revolute" name="right_back_wheel_hinge">
        <pose>0 0 .1 0 0 0</pose>
        <child>right_back_wheel</child>
        <parent>chassis</parent>
        <axis>
          <xyz>0 1 0</xyz>
        </axis>
      </joint>


      <joint type="revolute" name="left_middle_wheel_hinge">
        <pose>0 0 .1 0 0 0</pose>
        <child>left_middle_wheel</child>
        <parent>chassis</parent>
        <axis>
          <xyz>0 1 0</xyz>
        </axis>
      </joint>


      <joint type="revolute" name="right_middle_wheel_hinge">
        <pose>0 0 .1 0 0 0</pose>
        <child>right_middle_wheel</child>
        <parent>chassis</parent>
        <axis>
          <xyz>0 1 0</xyz>
        </axis>
      </joint>


      <joint type="revolute" name="left_back_wheel_hinge">
        <pose>0 0 .1 0 0 0</pose>
        <child>left_back_wheel</child>
        <parent>chassis</parent>
        <axis>
          <xyz>0 1 0</xyz>
        </axis>
      </joint>


      <joint type="revolute" name="right_front_wheel_hinge">
        <pose>0 0 .1 0 0 0</pose>
        <child>right_front_wheel</child>
        <parent>chassis</parent>
        <axis>
          <xyz>0 1 0</xyz>
        </axis>
      </joint>


      <joint type="fixed" name="indicator_joint">
        <pose>0 0 0 0 0 0</pose>
        <child>front_indicator</child>
        <parent>chassis</parent>
      </joint>

      <joint type="fixed" name="rf_foot_joint">
        <pose>0 0 0 0 0 0</pose>
        <child>right_front_foot</child>
        <parent>right_front_wheel</parent>
      </joint>

      <joint type="fixed" name="rm_foot_joint">
        <pose>0 0 0 0 0 0</pose>
        <child>right_middle_foot</child>
        <parent>right_middle_wheel</parent>
      </joint>

      <joint type="fixed" name="lm_foot_joint">
        <pose>0 0 0 0 0 0</pose>
        <child>left_middle_foot</child>
        <parent>left_middle_wheel</parent>
      </joint>
      
      <joint type="fixed" name="lb_foot_joint">
        <pose>0 0 0 0 0 0</pose>
        <child>left_back_foot</child>
        <parent>left_back_wheel</parent>
      </joint>

      <joint type="fixed" name="rb_foot_joint">
        <pose>0 0 0 0 0 0</pose>
        <child>right_back_foot</child>
        <parent>right_back_wheel</parent>
      </joint>
      
      <joint type="fixed" name="lf_foot_joint">
        <pose>0 0 0 0 0 0</pose>
        <child>left_front_foot</child>
        <parent>left_front_wheel</parent>
      </joint>

      <plugin name="wheeledRobot" filename="libwheeledRobot.so"/>
    </model>
</world>
</sdf>