<?xml version='1.0'?>
<sdf version ='1.6'>    
	    <model name="car">
    <pose>1 -1.5 5.1 0 0 0</pose>
    <link name='chassis'>
          <pose>0 0 .1 0 0 0</pose>
          <inertial>
            <inertia>
              <ixx>1</ixx>
              <ixy>0</ixy>
              <ixz>0</ixz>
              <iyy>1</iyy>
              <iyz>0</iyz>
              <izz>1</izz>
            </inertia>
            <mass>5.0</mass>
          </inertial>
          <collision name='collision'>
            <geometry>
              <box>
                <size>1 .5 .1</size>
              </box>
            </geometry>
          </collision>

          <visual name='visual'>
            <geometry>
              <box>
                <size>1 .5 .1</size>
              </box>
            </geometry>
          <material>
            <script>
              <name>ModelPreview_2::left_front_wheel::visual_MATERIAL_</name>
            </script>
            <ambient>1 0 0 1</ambient>
            <shader type='vertex'>
              <normal_map>__default__</normal_map>
            </shader>
        </material>
          </visual>
      </link>

      <link name="front_indicator">
        <pose>.5 0 0.18 0 0 0</pose>
          <geometry>
              <sphere>
              <radius>.03</radius>
            </sphere>
          </geometry>
        <visual name="visual">
          <geometry>
              <sphere>
              <radius>.03</radius>
            </sphere>
          </geometry>
          <material>Gazebo/Blue</material>
        </visual>
      </link>


      <link name="left_front_wheel">
        <pose>.5 .27 .1 1.5707 0 0</pose>
        <inertial>
          <inertia>
            <ixx>1</ixx>
            <ixy>0</ixy>
            <ixz>0</ixz>
            <iyy>1</iyy>
            <iyz>0</iyz>
            <izz>1</izz>
          </inertia>
          <mass>1.0</mass>
        </inertial>
        <collision name="collision">
          <geometry>
            <cylinder>
              <radius>.2</radius>
              <length>.1</length>
            </cylinder>
          </geometry>
        </collision>
        <visual name="visual">
          <geometry>
            <cylinder>
              <radius>.2</radius>
              <length>.1</length>
            </cylinder>
          </geometry>
        </visual>
      </link>


      <link name="right_front_wheel">
        <pose>.5 -.27 .1 1.5707 0 0</pose>
        <inertial>
          <inertia>
            <ixx>1</ixx>
            <ixy>0</ixy>
            <ixz>0</ixz>
            <iyy>1</iyy>
            <iyz>0</iyz>
            <izz>1</izz>
          </inertia>
          <mass>1.0</mass>
        </inertial>
        <collision name="collision">
          <geometry>
            <cylinder>
              <radius>.2</radius>
              <length>.1</length>
            </cylinder>
          </geometry>
        </collision>
        <visual name="visual">
          <geometry>
            <cylinder>
              <radius>.2</radius>
              <length>.1</length>
            </cylinder>
          </geometry>
        </visual>
      </link>



      <link name="left_back_wheel">
        <pose>-.5 .27 .1 1.5707 0 0</pose>
        <inertial>
          <inertia>
            <ixx>1</ixx>
            <ixy>0</ixy>
            <ixz>0</ixz>
            <iyy>1</iyy>
            <iyz>0</iyz>
            <izz>1</izz>
          </inertia>
          <mass>1.0</mass>
        </inertial>
        <collision name="collision">
          <geometry>
            <cylinder>
              <radius>.2</radius>
              <length>.1</length>
            </cylinder>
          </geometry>
        </collision>
        <visual name="visual">
          <geometry>
            <cylinder>
              <radius>.2</radius>
              <length>.1</length>
            </cylinder>
          </geometry>
          <material>
            <script>
              <name>ModelPreview_2::left_front_wheel::visual_MATERIAL_</name>
            </script>
            <ambient>0 0 0 1</ambient>
            <shader type='vertex'>
              <normal_map>__default__</normal_map>
            </shader>
          </material>
        </visual>
      </link>


      <link name="right_back_wheel">
        <pose>-.5 -.27 .1 1.5707 0 0</pose>
        <inertial>
          <inertia>
            <ixx>1</ixx>
            <ixy>0</ixy>
            <ixz>0</ixz>
            <iyy>1</iyy>
            <iyz>0</iyz>
            <izz>1</izz>
          </inertia>
          <mass>1.0</mass>
        </inertial>
        <collision name="collision">
          <geometry>
            <cylinder>
              <radius>.2</radius>
              <length>.1</length>
            </cylinder>
          </geometry>
        </collision>
        <visual name="visual">
          <geometry>
            <cylinder>
              <radius>.2</radius>
              <length>.1</length>
            </cylinder>
          </geometry>
          <material>
            <script>
              <name>ModelPreview_2::left_front_wheel::visual_MATERIAL_</name>
            </script>
            <ambient>0 0 0 1</ambient>
            <shader type='vertex'>
              <normal_map>__default__</normal_map>
            </shader>
          </material>
        </visual>
      </link>


      <joint type="revolute" name="left_front_wheel_hinge">
        <pose>0 0 0 0 0 0</pose>
        <child>left_front_wheel</child>
        <parent>chassis</parent>
        <axis>
          <xyz>0 1 0</xyz>
        </axis>
      </joint>


      <joint type="revolute" name="right_back_wheel_hinge">
        <pose>0 0 0 0 0 0</pose>
        <child>right_back_wheel</child>
        <parent>chassis</parent>
        <axis>
          <xyz>0 1 0</xyz>
        </axis>
      </joint>



      <joint type="revolute" name="left_back_wheel_hinge">
        <pose>0 0 0 0 0 0</pose>
        <child>left_back_wheel</child>
        <parent>chassis</parent>
        <axis>
          <xyz>0 1 0</xyz>
        </axis>
      </joint>

      

      <joint type="revolute" name="right_front_wheel_hinge">
        <pose>0 0 0 0 0 0</pose>
        <child>right_front_wheel</child>
        <parent>chassis</parent>
        <axis>
          <xyz>0 1 0</xyz>
        </axis>
      </joint>

      <joint type="fixed" name="indicator_joint">
        <pose>0 0 0 0 0 0</pose>
        <child>front_indicator</child>
        <parent>chassis</parent>
      </joint>

      <plugin name="wheeledRobot" filename="libwheeledRobot.so"/>
    </model>
</sdf>
